Workbook

Sheet Test Cases
A1: Test Case ID | B1: Module | C1: Sub Feature | D1: Scenario Type | E1: Priority | F1: Severity | G1: Tags | H1: Title | I1: Preconditions | J1: Test Data | K1: Steps | L1: Expected Result | M1: Execution Status | N1: Actual Result | O1: Defect ID | P1: Automation Candidate | Q1: Automation Priority | R1: Notes
A2: SD-UI-TC-001 | B2: Login | C2: Authentication | D2: Positive | E2: Critical | F2: High | G2: @smoke @regression @login | H2: Valid standard user can log in successfully | I2: 1. Navigate to https://www.saucedemo.com/ 2. Browser session is clean or app state has been reset 3. Use documented SauceDemo test credentials | J2: Username: standard_user Password: secret_sauce | K2: 1. Enter standard_user in Username 2. Enter secret_sauce in Password 3. Click Login | L2: 1. User is redirected to /inventory.html 2. Products page title is displayed 3. Product cards are visible | M2: Pass | N2: Passed in Playwright regression run: 84/84 automated tests passed. | P2: Yes | Q2: High | R2: Automated in Playwright JavaScript using Page Object Model.
A3: SD-UI-TC-002 | B3: Login | C3: Authentication | D3: Negative | E3: Critical | F3: High | G3: @sanity @regression @login @negative | H3: Locked out user cannot log in | I3: 1. Navigate to https://www.saucedemo.com/ 2. Browser session is clean or app state has been reset 3. Use documented SauceDemo test credentials | J3: Username: locked_out_user Password: secret_sauce | K3: 1. Enter locked_out_user 2. Enter secret_sauce 3. Click Login | L3: 1. Login fails 2. Error banner displays: Epic sadface: Sorry, this user has been locked out. 3. User remains on login page | M3: Pass | N3: Passed in Playwright regression run: 84/84 automated tests passed. | P3: Yes | Q3: High | R3: Automated in Playwright JavaScript using Page Object Model.
A4: SD-UI-TC-003 | B4: Login | C4: Validation | D4: Negative | E4: High | F4: Medium | G4: @sanity @regression @login @negative | H4: Login requires username when both fields are empty | I4: 1. Navigate to https://www.saucedemo.com/ 2. Browser session is clean or app state has been reset 3. Use documented SauceDemo test credentials | J4: Username: blank Password: blank | K4: 1. Leave Username empty 2. Leave Password empty 3. Click Login | L4: 1. Error banner displays: Epic sadface: Username is required 2. User remains on login page | M4: Pass | N4: Passed in Playwright regression run: 84/84 automated tests passed. | P4: Yes | Q4: High | R4: Automated in Playwright JavaScript using Page Object Model.
A5: SD-UI-TC-004 | B5: Login | C5: Validation | D5: Negative | E5: High | F5: Medium | G5: @sanity @regression @login @negative | H5: Login requires password when password is empty | I5: 1. Navigate to https://www.saucedemo.com/ 2. Browser session is clean or app state has been reset 3. Use documented SauceDemo test credentials | J5: Username: standard_user Password: blank | K5: 1. Enter standard_user 2. Leave Password empty 3. Click Login | L5: 1. Error banner displays required-password error or equivalent validation 2. User remains on login page | M5: Pass | N5: Passed in Playwright regression run: 84/84 automated tests passed. | P5: Yes | Q5: High | R5: Automated in Playwright JavaScript using Page Object Model.
A6: SD-UI-TC-005 | B6: Login | C6: Validation | D6: Negative | E6: High | F6: Medium | G6: @regression @login @negative | H6: Invalid username and valid password are rejected | I6: 1. Navigate to https://www.saucedemo.com/ 2. Browser session is clean or app state has been reset 3. Use documented SauceDemo test credentials | J6: Username: invalid_user Password: secret_sauce | K6: 1. Enter invalid_user 2. Enter secret_sauce 3. Click Login | L6: 1. Login fails 2. Error banner displays username/password mismatch message | M6: Pass | N6: Passed in Playwright regression run: 84/84 automated tests passed. | P6: Yes | Q6: Medium | R6: Automated in Playwright JavaScript using Page Object Model.
A7: SD-UI-TC-006 | B7: Login | C7: Validation | D7: Negative | E7: High | F7: Medium | G7: @regression @login @negative | H7: Valid username and invalid password are rejected | I7: 1. Navigate to https://www.saucedemo.com/ 2. Browser session is clean or app state has been reset 3. Use documented SauceDemo test credentials | J7: Username: standard_user Password: wrong_password | K7: 1. Enter standard_user 2. Enter wrong_password 3. Click Login | L7: 1. Login fails 2. Error banner displays username/password mismatch message | M7: Pass | N7: Passed in Playwright regression run: 84/84 automated tests passed. | P7: Yes | Q7: Medium | R7: Automated in Playwright JavaScript using Page Object Model.
A8: SD-UI-TC-007 | B8: Login | C8: Validation | D8: Edge Case | E8: Medium | F8: Low | G8: @regression @login @edge | H8: Username with leading and trailing spaces is rejected | I8: 1. Navigate to https://www.saucedemo.com/ 2. Browser session is clean or app state has been reset 3. Use documented SauceDemo test credentials | J8: Username: standard_user Password: secret_sauce | K8: 1. Enter username with leading and trailing spaces 2. Enter secret_sauce 3. Click Login | L8: 1. Login result follows application behavior consistently 2. If rejected, mismatch error is displayed | M8: Untested | P8: Later | Q8: Low
A9: SD-UI-TC-008 | B9: Login | C9: Validation | D9: Edge Case | E9: Medium | F9: Low | G9: @regression @login @edge | H9: Password value is case sensitive | I9: 1. Navigate to https://www.saucedemo.com/ 2. Browser session is clean or app state has been reset 3. Use documented SauceDemo test credentials | J9: Username: standard_user Password: Secret_Sauce | K9: 1. Enter standard_user 2. Enter Secret_Sauce 3. Click Login | L9: 1. Login fails 2. Mismatch error is displayed | M9: Pass | N9: Passed in Playwright regression run: 84/84 automated tests passed. | P9: Yes | Q9: Low | R9: Automated in Playwright JavaScript using Page Object Model.
A10: SD-UI-TC-009 | B10: Login | C10: UI | D10: UI Validation | E10: Medium | F10: Low | G10: @regression @login @ui | H10: Login page displays accepted username and password hints | I10: 1. Navigate to https://www.saucedemo.com/ 2. Browser session is clean or app state has been reset 3. Use documented SauceDemo test credentials | J10: N/A | K10: 1. Open login page 2. Review accepted usernames section 3. Review password hint section | L10: 1. All documented usernames are displayed 2. Password hint displays secret_sauce | M10: Untested | P10: No | Q10: N/A
A11: SD-UI-TC-010 | B11: Login | C11: UI | D11: UI Validation | E11: Medium | F11: Low | G11: @regression @login @ui | H11: Login fields and button are visible and enabled | I11: 1. Navigate to https://www.saucedemo.com/ 2. Browser session is clean or app state has been reset 3. Use documented SauceDemo test credentials | J11: N/A | K11: 1. Open login page 2. Inspect Username field 3. Inspect Password field 4. Inspect Login button | L11: 1. Username field is visible 2. Password field is visible 3. Login button is visible and enabled | M11: Pass | N11: Passed in Playwright regression run: 84/84 automated tests passed. | P11: Yes | Q11: Low | R11: Automated in Playwright JavaScript using Page Object Model.
A12: SD-UI-TC-011 | B12: Login | C12: Session | D12: Positive | E12: High | F12: Medium | G12: @sanity @regression @login | H12: Authenticated user cannot stay on login page after successful login | I12: 1. Navigate to https://www.saucedemo.com/ 2. Browser session is clean or app state has been reset 3. Use documented SauceDemo test credentials | J12: Username: standard_user Password: secret_sauce | K12: 1. Log in as standard_user 2. Confirm inventory page is shown 3. Navigate browser back if applicable | L12: 1. Application maintains a consistent authenticated state 2. Protected page access remains valid while session is active | M12: Untested | P12: Later | Q12: Medium
A13: SD-UI-TC-012 | B13: Login | C13: Session | D13: Edge Case | E13: Medium | F13: Low | G13: @regression @login @edge | H13: Refresh login page does not prefill sensitive password data | I13: 1. Navigate to https://www.saucedemo.com/ 2. Browser session is clean or app state has been reset 3. Use documented SauceDemo test credentials | J13: N/A | K13: 1. Open login page 2. Enter credentials 3. Refresh before clicking Login | L13: 1. Password field is not unexpectedly persisted 2. Page remains usable after refresh | M13: Untested | P13: No | Q13: N/A
A14: SD-UI-TC-013 | B14: Login | C14: Authentication | D14: Positive | E14: High | F14: Medium | G14: @regression @login @user | H14: problem_user can authenticate | I14: 1. Navigate to https://www.saucedemo.com/ 2. Browser session is clean or app state has been reset 3. Use documented SauceDemo test credentials | J14: Username: problem_user Password: secret_sauce | K14: 1. Enter problem_user 2. Enter secret_sauce 3. Click Login | L14: 1. User reaches inventory page 2. Products page loads with known problem_user behavior | M14: Pass | N14: Passed in Playwright regression run: 84/84 automated tests passed. | P14: Yes | Q14: Medium | R14: Automated in Playwright JavaScript using Page Object Model.
A15: SD-UI-TC-014 | B15: Login | C15: Authentication | D15: Positive | E15: High | F15: Medium | G15: @regression @login @performance | H15: performance_glitch_user can authenticate with delayed response | I15: 1. Navigate to https://www.saucedemo.com/ 2. Browser session is clean or app state has been reset 3. Use documented SauceDemo test credentials | J15: Username: performance_glitch_user Password: secret_sauce | K15: 1. Enter performance_glitch_user 2. Enter secret_sauce 3. Click Login 4. Wait for inventory page | L15: 1. User reaches inventory page after intentional delay 2. Test documents observed delay | M15: Pass | N15: Passed in Playwright regression run: 84/84 automated tests passed. | P15: Yes | Q15: Medium | R15: Automated in Playwright JavaScript using Page Object Model.
A16: SD-UI-TC-015 | B16: Login | C16: Authentication | D16: Positive | E16: Medium | F16: Medium | G16: @regression @login @user | H16: error_user can authenticate | I16: 1. Navigate to https://www.saucedemo.com/ 2. Browser session is clean or app state has been reset 3. Use documented SauceDemo test credentials | J16: Username: error_user Password: secret_sauce | K16: 1. Enter error_user 2. Enter secret_sauce 3. Click Login | L16: 1. User reaches inventory page 2. Known error-user behavior can be tested | M16: Untested | P16: Later | Q16: Medium
A17: SD-UI-TC-016 | B17: Login | C17: Authentication | D17: Positive | E17: Medium | F17: Medium | G17: @regression @login @visual | H17: visual_user can authenticate | I17: 1. Navigate to https://www.saucedemo.com/ 2. Browser session is clean or app state has been reset 3. Use documented SauceDemo test credentials | J17: Username: visual_user Password: secret_sauce | K17: 1. Enter visual_user 2. Enter secret_sauce 3. Click Login | L17: 1. User reaches inventory page 2. Known visual differences are observable | M17: Untested | P17: Later | Q17: Low
A18: SD-UI-TC-017 | B18: Inventory / Product Listing | C18: Page Load | D18: Positive | E18: Critical | F18: High | G18: @smoke @regression @inventory | H18: Inventory page loads after login | I18: 1. User is logged in as standard_user 2. Cart state is empty before starting 3. User is on the expected starting page | J18: Username: standard_user Password: secret_sauce | K18: 1. Log in as standard_user 2. Observe inventory page | L18: 1. URL is /inventory.html 2. Products title is displayed 3. Product grid is visible | M18: Pass | N18: Passed in Playwright regression run: 84/84 automated tests passed. | P18: Yes | Q18: High | R18: Automated in Playwright JavaScript using Page Object Model.
A19: SD-UI-TC-018 | B19: Inventory / Product Listing | C19: Product Grid | D19: Positive | E19: High | F19: High | G19: @smoke @regression @inventory | H19: All six products are displayed | I19: 1. User is logged in as standard_user 2. Cart state is empty before starting 3. User is on the expected starting page | J19: Expected product count: 6 | K19: 1. Open inventory page 2. Count product cards | L19: 1. Exactly six product cards are displayed 2. Each card has name, image, description, price, and add button | M19: Pass | N19: Passed in Playwright regression run: 84/84 automated tests passed. | P19: Yes | Q19: High | R19: Automated in Playwright JavaScript using Page Object Model.
A20: SD-UI-TC-019 | B20: Inventory / Product Listing | C20: Product Data | D20: Positive | E20: High | F20: Medium | G20: @regression @inventory @catalog | H20: Inventory product names match catalog | I20: 1. User is logged in as standard_user 2. Cart state is empty before starting 3. User is on the expected starting page | J20: Six documented SauceDemo product names | K20: 1. Open inventory page 2. Compare product names with catalog | L20: 1. All six expected product names are present 2. No unexpected product names are shown | M20: Pass | N20: Passed in Playwright regression run: 84/84 automated tests passed. | P20: Yes | Q20: Medium | R20: Automated in Playwright JavaScript using Page Object Model.
A21: SD-UI-TC-020 | B21: Inventory / Product Listing | C21: Product Data | D21: Positive | E21: High | F21: Medium | G21: @regression @inventory @catalog | H21: Inventory product prices match catalog | I21: 1. User is logged in as standard_user 2. Cart state is empty before starting 3. User is on the expected starting page | J21: Expected prices: 29.99, 9.99, 15.99, 49.99, 7.99, 15.99 | K21: 1. Open inventory page 2. Compare displayed prices with catalog | L21: 1. Every product price matches documented value 2. Prices display USD currency format | M21: Pass | N21: Passed in Playwright regression run: 84/84 automated tests passed. | P21: Yes | Q21: Medium | R21: Automated in Playwright JavaScript using Page Object Model.
A22: SD-UI-TC-021 | B22: Inventory / Product Listing | C22: Product Card | D22: UI Validation | E22: Medium | F22: Low | G22: @regression @inventory @ui | H22: Each product card displays required UI elements | I22: 1. User is logged in as standard_user 2. Cart state is empty before starting 3. User is on the expected starting page | J22: N/A | K22: 1. Open inventory page 2. Inspect each product card | L22: 1. Image, name, description, price, and Add to Cart button are visible for each product | M22: Untested | P22: Later | Q22: Low
A23: SD-UI-TC-022 | B23: Inventory / Product Listing | C23: Add to Cart | D23: Positive | E23: Critical | F23: High | G23: @smoke @regression @cart @inventory | H23: Add one product from inventory | I23: 1. User is logged in as standard_user 2. Cart state is empty before starting 3. User is on the expected starting page | J23: Product: Sauce Labs Backpack | K23: 1. Click Add to Cart for Sauce Labs Backpack | L23: 1. Button changes to Remove 2. Cart badge displays 1 | M23: Pass | N23: Passed in Playwright regression run: 84/84 automated tests passed. | P23: Yes | Q23: High | R23: Automated in Playwright JavaScript using Page Object Model.
A24: SD-UI-TC-023 | B24: Inventory / Product Listing | C24: Add to Cart | D24: Positive | E24: High | F24: High | G24: @regression @cart @inventory | H24: Add multiple products from inventory | I24: 1. User is logged in as standard_user 2. Cart state is empty before starting 3. User is on the expected starting page | J24: Products: Backpack, Bike Light, Onesie | K24: 1. Click Add to Cart for three products | L24: 1. Each selected product button changes to Remove 2. Cart badge displays 3 | M24: Pass | N24: Passed in Playwright regression run: 84/84 automated tests passed. | P24: Yes | Q24: High | R24: Automated in Playwright JavaScript using Page Object Model.
A25: SD-UI-TC-024 | B25: Inventory / Product Listing | C25: Remove | D25: Positive | E25: High | F25: Medium | G25: @sanity @regression @cart @inventory | H25: Remove added product from inventory page | I25: 1. User is logged in as standard_user 2. Cart state is empty before starting 3. User is on the expected starting page | J25: Product: Sauce Labs Backpack | K25: 1. Add Backpack 2. Click Remove for Backpack | L25: 1. Button changes back to Add to Cart 2. Cart badge is cleared | M25: Pass | N25: Passed in Playwright regression run: 84/84 automated tests passed. | P25: Yes | Q25: High | R25: Automated in Playwright JavaScript using Page Object Model.
A26: SD-UI-TC-025 | B26: Inventory / Product Listing | C26: Badge | D26: Edge Case | E26: High | F26: Medium | G26: @regression @cart @inventory @edge | H26: Cart badge updates correctly when adding and removing several items | I26: 1. User is logged in as standard_user 2. Cart state is empty before starting 3. User is on the expected starting page | J26: Products: Backpack, Bike Light, Onesie | K26: 1. Add three products 2. Remove one product 3. Add another product | L26: 1. Badge count equals current selected item count after every action | M26: Pass | N26: Passed in Playwright regression run: 84/84 automated tests passed. | P26: Yes | Q26: Medium | R26: Automated in Playwright JavaScript using Page Object Model.
A27: SD-UI-TC-026 | B27: Inventory / Product Listing | C27: Sorting | D27: Positive | E27: High | F27: Medium | G27: @regression @inventory @sort | H27: Default sort order is Name A to Z | I27: 1. User is logged in as standard_user 2. Cart state is empty before starting 3. User is on the expected starting page | J27: Sort option: Name A to Z | K27: 1. Open inventory page 2. Read product names top to bottom | L27: 1. Products are ordered alphabetically A to Z by name | M27: Pass | N27: Passed in Playwright regression run: 84/84 automated tests passed. | P27: Yes | Q27: High | R27: Automated in Playwright JavaScript using Page Object Model.
A28: SD-UI-TC-027 | B28: Inventory / Product Listing | C28: Sorting | D28: Positive | E28: High | F28: Medium | G28: @regression @inventory @sort | H28: Sort products by Name Z to A | I28: 1. User is logged in as standard_user 2. Cart state is empty before starting 3. User is on the expected starting page | J28: Sort option: Name Z to A | K28: 1. Select Name Z to A from sort dropdown 2. Read product names top to bottom | L28: 1. Products are ordered alphabetically Z to A | M28: Pass | N28: Passed in Playwright regression run: 84/84 automated tests passed. | P28: Yes | Q28: High | R28: Automated in Playwright JavaScript using Page Object Model.
A29: SD-UI-TC-028 | B29: Inventory / Product Listing | C29: Sorting | D29: Positive | E29: High | F29: Medium | G29: @regression @inventory @sort | H29: Sort products by Price low to high | I29: 1. User is logged in as standard_user 2. Cart state is empty before starting 3. User is on the expected starting page | J29: Sort option: Price low to high | K29: 1. Select Price low to high 2. Read product prices top to bottom | L29: 1. Products are ordered from $7.99 to $49.99 | M29: Pass | N29: Passed in Playwright regression run: 84/84 automated tests passed. | P29: Yes | Q29: High | R29: Automated in Playwright JavaScript using Page Object Model.
A30: SD-UI-TC-029 | B30: Inventory / Product Listing | C30: Sorting | D30: Positive | E30: High | F30: Medium | G30: @regression @inventory @sort | H30: Sort products by Price high to low | I30: 1. User is logged in as standard_user 2. Cart state is empty before starting 3. User is on the expected starting page | J30: Sort option: Price high to low | K30: 1. Select Price high to low 2. Read product prices top to bottom | L30: 1. Products are ordered from $49.99 to $7.99 | M30: Pass | N30: Passed in Playwright regression run: 84/84 automated tests passed. | P30: Yes | Q30: High | R30: Automated in Playwright JavaScript using Page Object Model.
A31: SD-UI-TC-030 | B31: Inventory / Product Listing | C31: Sorting | D31: Edge Case | E31: Medium | F31: Low | G31: @regression @inventory @sort @edge | H31: Sorting does not clear already selected cart items | I31: 1. User is logged in as standard_user 2. Cart state is empty before starting 3. User is on the expected starting page | J31: Product: Backpack; Sort: Price low to high | K31: 1. Add Backpack to cart 2. Change sort order 3. Observe Backpack card and cart badge | L31: 1. Backpack remains selected 2. Remove button remains visible for selected item 3. Cart badge remains 1 | M31: Pass | N31: Passed in Playwright regression run: 84/84 automated tests passed. | P31: Yes | Q31: Medium | R31: Automated in Playwright JavaScript using Page Object Model.
A32: SD-UI-TC-031 | B32: Inventory / Product Listing | C32: Navigation | D32: Positive | E32: High | F32: Medium | G32: @regression @inventory @product-detail | H32: Click product name opens product detail page | I32: 1. User is logged in as standard_user 2. Cart state is empty before starting 3. User is on the expected starting page | J32: Product: Sauce Labs Backpack | K32: 1. Click Sauce Labs Backpack product name | L32: 1. Product detail page opens 2. Displayed product is Sauce Labs Backpack | M32: Pass | N32: Passed in Playwright regression run: 84/84 automated tests passed. | P32: Yes | Q32: Medium | R32: Automated in Playwright JavaScript using Page Object Model.
A33: SD-UI-TC-032 | B33: Inventory / Product Listing | C33: Navigation | D33: Positive | E33: Medium | F33: Low | G33: @regression @inventory @product-detail | H33: Click product image opens product detail page | I33: 1. User is logged in as standard_user 2. Cart state is empty before starting 3. User is on the expected starting page | J33: Product: Sauce Labs Bike Light | K33: 1. Click Sauce Labs Bike Light image | L33: 1. Product detail page opens 2. Displayed product is Sauce Labs Bike Light | M33: Untested | P33: Later | Q33: Low
A34: SD-UI-TC-033 | B34: Inventory / Product Listing | C34: Cart Navigation | D34: Positive | E34: High | F34: Medium | G34: @sanity @regression @cart @inventory | H34: Cart icon opens shopping cart page | I34: 1. User is logged in as standard_user 2. Cart state is empty before starting 3. User is on the expected starting page | J34: N/A | K34: 1. Click cart icon from inventory page | L34: 1. User is navigated to /cart.html 2. Your Cart title is displayed | M34: Pass | N34: Passed in Playwright regression run: 84/84 automated tests passed. | P34: Yes | Q34: High | R34: Automated in Playwright JavaScript using Page Object Model.
A35: SD-UI-TC-034 | B35: Inventory / Product Listing | C35: Access Control | D35: Negative | E35: High | F35: High | G35: @regression @inventory @security @negative | H35: Unauthenticated user cannot directly access inventory page | I35: 1. User is logged out 2. Browser session is clean | J35: URL: /inventory.html | K35: 1. Open /inventory.html directly without login | L35: 1. User is redirected to login page or blocked consistently 2. Protected content is not usable without authentication | M35: Untested | P35: Later | Q35: Medium
A36: SD-UI-TC-035 | B36: Product Detail | C36: Page Load | D36: Positive | E36: High | F36: Medium | G36: @sanity @regression @product-detail | H36: Product detail page displays selected product information | I36: 1. User is logged in as standard_user 2. Cart state is empty before starting 3. User is on the expected starting page | J36: Product: Sauce Labs Backpack | K36: 1. Open Backpack detail page from inventory 2. Inspect detail content | L36: 1. Product name, description, image, and price match inventory card | M36: Pass | N36: Passed in Playwright regression run: 84/84 automated tests passed. | P36: Yes | Q36: High | R36: Automated in Playwright JavaScript using Page Object Model.
A37: SD-UI-TC-036 | B37: Product Detail | C37: Back Navigation | D37: Positive | E37: High | F37: Medium | G37: @regression @product-detail | H37: Back to Products returns to inventory page | I37: 1. User is logged in as standard_user 2. Cart state is empty before starting 3. User is on the expected starting page | J37: N/A | K37: 1. Open any product detail page 2. Click Back to Products | L37: 1. User returns to /inventory.html 2. Products page title is displayed | M37: Pass | N37: Passed in Playwright regression run: 84/84 automated tests passed. | P37: Yes | Q37: Medium | R37: Automated in Playwright JavaScript using Page Object Model.
A38: SD-UI-TC-037 | B38: Product Detail | C38: Cart | D38: Positive | E38: High | F38: Medium | G38: @regression @product-detail @cart | H38: Add product to cart from detail page | I38: 1. User is logged in as standard_user 2. Cart state is empty before starting 3. User is on the expected starting page | J38: Product: Sauce Labs Fleece Jacket | K38: 1. Open Fleece Jacket detail page 2. Click Add to Cart | L38: 1. Button changes to Remove 2. Cart badge displays 1 | M38: Pass | N38: Passed in Playwright regression run: 84/84 automated tests passed. | P38: Yes | Q38: High | R38: Automated in Playwright JavaScript using Page Object Model.
A39: SD-UI-TC-038 | B39: Product Detail | C39: Cart | D39: Positive | E39: High | F39: Medium | G39: @regression @product-detail @cart | H39: Remove product from cart from detail page | I39: 1. User is logged in as standard_user 2. Cart state is empty before starting 3. User is on the expected starting page | J39: Product: Sauce Labs Fleece Jacket | K39: 1. Open Fleece Jacket detail page 2. Add product to cart 3. Click Remove | L39: 1. Button changes to Add to Cart 2. Cart badge is cleared | M39: Pass | N39: Passed in Playwright regression run: 84/84 automated tests passed. | P39: Yes | Q39: Medium | R39: Automated in Playwright JavaScript using Page Object Model.
A40: SD-UI-TC-039 | B40: Product Detail | C40: State | D40: Edge Case | E40: Medium | F40: Low | G40: @regression @product-detail @cart @edge | H40: Cart state is preserved between inventory and detail page | I40: 1. User is logged in as standard_user 2. Cart state is empty before starting 3. User is on the expected starting page | J40: Product: Sauce Labs Backpack | K40: 1. Add Backpack from inventory 2. Open Backpack detail page | L40: 1. Detail page shows Remove button 2. Cart badge remains 1 | M40: Pass | N40: Passed in Playwright regression run: 84/84 automated tests passed. | P40: Yes | Q40: Medium | R40: Automated in Playwright JavaScript using Page Object Model.
...

Sheet Coverage Matrix
A1: SauceDemo UI Manual Test Coverage Matrix
A2: Coverage summary by module and scenario type. Counts are formula-driven from the Test Cases sheet.
A4: Module | B4: Total | C4: Positive | D4: Negative | E4: Edge Case | F4: UI Validation | G4: E2E | H4: Known Bug
A5: Login | B5: =COUNTIF('Test Cases'!$B$2:$B$137,A5) -> 16 | C5: =COUNTIFS('Test Cases'!$B$2:$B$137,$A5,'Test Cases'!$D$2:$D$137,C$4) -> 6 | D5: =COUNTIFS('Test Cases'!$B$2:$B$137,$A5,'Test Cases'!$D$2:$D$137,D$4) -> 5 | E5: =COUNTIFS('Test Cases'!$B$2:$B$137,$A5,'Test Cases'!$D$2:$D$137,E$4) -> 3 | F5: =COUNTIFS('Test Cases'!$B$2:$B$137,$A5,'Test Cases'!$D$2:$D$137,F$4) -> 2 | G5: =COUNTIFS('Test Cases'!$B$2:$B$137,$A5,'Test Cases'!$D$2:$D$137,G$4) -> 0 | H5: =COUNTIFS('Test Cases'!$B$2:$B$137,$A5,'Test Cases'!$D$2:$D$137,H$4) -> 0
A6: Inventory / Product Listing | B6: =COUNTIF('Test Cases'!$B$2:$B$137,A6) -> 18 | C6: =COUNTIFS('Test Cases'!$B$2:$B$137,$A6,'Test Cases'!$D$2:$D$137,C$4) -> 14 | D6: =COUNTIFS('Test Cases'!$B$2:$B$137,$A6,'Test Cases'!$D$2:$D$137,D$4) -> 1 | E6: =COUNTIFS('Test Cases'!$B$2:$B$137,$A6,'Test Cases'!$D$2:$D$137,E$4) -> 2 | F6: =COUNTIFS('Test Cases'!$B$2:$B$137,$A6,'Test Cases'!$D$2:$D$137,F$4) -> 1 | G6: =COUNTIFS('Test Cases'!$B$2:$B$137,$A6,'Test Cases'!$D$2:$D$137,G$4) -> 0 | H6: =COUNTIFS('Test Cases'!$B$2:$B$137,$A6,'Test Cases'!$D$2:$D$137,H$4) -> 0
A7: Product Detail | B7: =COUNTIF('Test Cases'!$B$2:$B$137,A7) -> 10 | C7: =COUNTIFS('Test Cases'!$B$2:$B$137,$A7,'Test Cases'!$D$2:$D$137,C$4) -> 6 | D7: =COUNTIFS('Test Cases'!$B$2:$B$137,$A7,'Test Cases'!$D$2:$D$137,D$4) -> 1 | E7: =COUNTIFS('Test Cases'!$B$2:$B$137,$A7,'Test Cases'!$D$2:$D$137,E$4) -> 3 | F7: =COUNTIFS('Test Cases'!$B$2:$B$137,$A7,'Test Cases'!$D$2:$D$137,F$4) -> 0 | G7: =COUNTIFS('Test Cases'!$B$2:$B$137,$A7,'Test Cases'!$D$2:$D$137,G$4) -> 0 | H7: =COUNTIFS('Test Cases'!$B$2:$B$137,$A7,'Test Cases'!$D$2:$D$137,H$4) -> 0
A8: Cart | B8: =COUNTIF('Test Cases'!$B$2:$B$137,A8) -> 16 | C8: =COUNTIFS('Test Cases'!$B$2:$B$137,$A8,'Test Cases'!$D$2:$D$137,C$4) -> 9 | D8: =COUNTIFS('Test Cases'!$B$2:$B$137,$A8,'Test Cases'!$D$2:$D$137,D$4) -> 1 | E8: =COUNTIFS('Test Cases'!$B$2:$B$137,$A8,'Test Cases'!$D$2:$D$137,E$4) -> 6 | F8: =COUNTIFS('Test Cases'!$B$2:$B$137,$A8,'Test Cases'!$D$2:$D$137,F$4) -> 0 | G8: =COUNTIFS('Test Cases'!$B$2:$B$137,$A8,'Test Cases'!$D$2:$D$137,G$4) -> 0 | H8: =COUNTIFS('Test Cases'!$B$2:$B$137,$A8,'Test Cases'!$D$2:$D$137,H$4) -> 0
A9: Checkout Information | B9: =COUNTIF('Test Cases'!$B$2:$B$137,A9) -> 14 | C9: =COUNTIFS('Test Cases'!$B$2:$B$137,$A9,'Test Cases'!$D$2:$D$137,C$4) -> 3 | D9: =COUNTIFS('Test Cases'!$B$2:$B$137,$A9,'Test Cases'!$D$2:$D$137,D$4) -> 5 | E9: =COUNTIFS('Test Cases'!$B$2:$B$137,$A9,'Test Cases'!$D$2:$D$137,E$4) -> 5 | F9: =COUNTIFS('Test Cases'!$B$2:$B$137,$A9,'Test Cases'!$D$2:$D$137,F$4) -> 1 | G9: =COUNTIFS('Test Cases'!$B$2:$B$137,$A9,'Test Cases'!$D$2:$D$137,G$4) -> 0 | H9: =COUNTIFS('Test Cases'!$B$2:$B$137,$A9,'Test Cases'!$D$2:$D$137,H$4) -> 0
A10: Checkout Overview | B10: =COUNTIF('Test Cases'!$B$2:$B$137,A10) -> 12 | C10: =COUNTIFS('Test Cases'!$B$2:$B$137,$A10,'Test Cases'!$D$2:$D$137,C$4) -> 8 | D10: =COUNTIFS('Test Cases'!$B$2:$B$137,$A10,'Test Cases'!$D$2:$D$137,D$4) -> 1 | E10: =COUNTIFS('Test Cases'!$B$2:$B$137,$A10,'Test Cases'!$D$2:$D$137,E$4) -> 1 | F10: =COUNTIFS('Test Cases'!$B$2:$B$137,$A10,'Test Cases'!$D$2:$D$137,F$4) -> 2 | G10: =COUNTIFS('Test Cases'!$B$2:$B$137,$A10,'Test Cases'!$D$2:$D$137,G$4) -> 0 | H10: =COUNTIFS('Test Cases'!$B$2:$B$137,$A10,'Test Cases'!$D$2:$D$137,H$4) -> 0
A11: Checkout Complete | B11: =COUNTIF('Test Cases'!$B$2:$B$137,A11) -> 7 | C11: =COUNTIFS('Test Cases'!$B$2:$B$137,$A11,'Test Cases'!$D$2:$D$137,C$4) -> 3 | D11: =COUNTIFS('Test Cases'!$B$2:$B$137,$A11,'Test Cases'!$D$2:$D$137,D$4) -> 1 | E11: =COUNTIFS('Test Cases'!$B$2:$B$137,$A11,'Test Cases'!$D$2:$D$137,E$4) -> 2 | F11: =COUNTIFS('Test Cases'!$B$2:$B$137,$A11,'Test Cases'!$D$2:$D$137,F$4) -> 1 | G11: =COUNTIFS('Test Cases'!$B$2:$B$137,$A11,'Test Cases'!$D$2:$D$137,G$4) -> 0 | H11: =COUNTIFS('Test Cases'!$B$2:$B$137,$A11,'Test Cases'!$D$2:$D$137,H$4) -> 0
A12: Navigation Menu | B12: =COUNTIF('Test Cases'!$B$2:$B$137,A12) -> 9 | C12: =COUNTIFS('Test Cases'!$B$2:$B$137,$A12,'Test Cases'!$D$2:$D$137,C$4) -> 6 | D12: =COUNTIFS('Test Cases'!$B$2:$B$137,$A12,'Test Cases'!$D$2:$D$137,D$4) -> 1 | E12: =COUNTIFS('Test Cases'!$B$2:$B$137,$A12,'Test Cases'!$D$2:$D$137,E$4) -> 1 | F12: =COUNTIFS('Test Cases'!$B$2:$B$137,$A12,'Test Cases'!$D$2:$D$137,F$4) -> 1 | G12: =COUNTIFS('Test Cases'!$B$2:$B$137,$A12,'Test Cases'!$D$2:$D$137,G$4) -> 0 | H12: =COUNTIFS('Test Cases'!$B$2:$B$137,$A12,'Test Cases'!$D$2:$D$137,H$4) -> 0
A13: User Types / Known Behaviors | B13: =COUNTIF('Test Cases'!$B$2:$B$137,A13) -> 14 | C13: =COUNTIFS('Test Cases'!$B$2:$B$137,$A13,'Test Cases'!$D$2:$D$137,C$4) -> 1 | D13: =COUNTIFS('Test Cases'!$B$2:$B$137,$A13,'Test Cases'!$D$2:$D$137,D$4) -> 1 | E13: =COUNTIFS('Test Cases'!$B$2:$B$137,$A13,'Test Cases'!$D$2:$D$137,E$4) -> 2 | F13: =COUNTIFS('Test Cases'!$B$2:$B$137,$A13,'Test Cases'!$D$2:$D$137,F$4) -> 1 | G13: =COUNTIFS('Test Cases'!$B$2:$B$137,$A13,'Test Cases'!$D$2:$D$137,G$4) -> 1 | H13: =COUNTIFS('Test Cases'!$B$2:$B$137,$A13,'Test Cases'!$D$2:$D$137,H$4) -> 8
A14: End-to-End Order Flow | B14: =COUNTIF('Test Cases'!$B$2:$B$137,A14) -> 20 | C14: =COUNTIFS('Test Cases'!$B$2:$B$137,$A14,'Test Cases'!$D$2:$D$137,C$4) -> 0 | D14: =COUNTIFS('Test Cases'!$B$2:$B$137,$A14,'Test Cases'!$D$2:$D$137,D$4) -> 0 | E14: =COUNTIFS('Test Cases'!$B$2:$B$137,$A14,'Test Cases'!$D$2:$D$137,E$4) -> 0 | F14: =COUNTIFS('Test Cases'!$B$2:$B$137,$A14,'Test Cases'!$D$2:$D$137,F$4) -> 0 | G14: =COUNTIFS('Test Cases'!$B$2:$B$137,$A14,'Test Cases'!$D$2:$D$137,G$4) -> 20 | H14: =COUNTIFS('Test Cases'!$B$2:$B$137,$A14,'Test Cases'!$D$2:$D$137,H$4) -> 0
A15: TOTAL | B15: =SUM(B5:B14) -> 136 | C15: =SUM(C5:C14) -> 56 | D15: =SUM(D5:D14) -> 17 | E15: =SUM(E5:E14) -> 25 | F15: =SUM(F5:F14) -> 9 | G15: =SUM(G5:G14) -> 21 | H15: =SUM(H5:H14) -> 8

Sheet Testing Progress
A1: SauceDemo Manual Testing Progress
A2: Update Execution Status in the Test Cases sheet. This dashboard recalculates the progress numbers automatically.
A4: Metric | B4: Value | D4: Status | E4: Count | F4: Share | G4: Execution Meaning | H4: Next Action
A5: Total Test Cases | B5: =COUNTA('Test Cases'!$A$2:$A$137) -> 136 | D5: Untested | E5: =COUNTIF('Test Cases'!$M$2:$M$137,D5) -> 52 | F5: =IF($B$5=0,0,E5/$B$5) -> 0.38235294 | G5: Not executed yet | H5: Execute or assign
A6: Untested | B6: =COUNTIF('Test Cases'!$M$2:$M$137,"Untested") -> 52 | D6: Pass | E6: =COUNTIF('Test Cases'!$M$2:$M$137,D6) -> 84 | F6: =IF($B$5=0,0,E6/$B$5) -> 0.61764706 | G6: Validated behavior | H6: Keep evidence
A7: Passed | B7: =COUNTIF('Test Cases'!$M$2:$M$137,"Pass") -> 84 | D7: Fail | E7: =COUNTIF('Test Cases'!$M$2:$M$137,D7) -> 0 | F7: =IF($B$5=0,0,E7/$B$5) -> 0 | G7: Defect candidate | H7: Add defect ID and notes
A8: Failed | B8: =COUNTIF('Test Cases'!$M$2:$M$137,"Fail") -> 0 | D8: Blocked | E8: =COUNTIF('Test Cases'!$M$2:$M$137,D8) -> 0 | F8: =IF($B$5=0,0,E8/$B$5) -> 0 | G8: Cannot execute | H8: Clarify blocker
A9: Blocked | B9: =COUNTIF('Test Cases'!$M$2:$M$137,"Blocked") -> 0 | D9: Skipped | E9: =COUNTIF('Test Cases'!$M$2:$M$137,D9) -> 0 | F9: =IF($B$5=0,0,E9/$B$5) -> 0 | G9: Out of current scope | H9: Revisit if needed
A10: Skipped | B10: =COUNTIF('Test Cases'!$M$2:$M$137,"Skipped") -> 0
A11: Executed | B11: =SUM(B7:B10) -> 84
A12: Completion Rate | B12: =IF(B5=0,0,B11/B5) -> 0.61764706
